Workbook
Name Lista_Combustible: Listas!$B$2:$B$4
Name Lista_Vehiculos: Listas!$A$2:$A$34
Name SegmentaciónDeDatos_Fecha: #N/A
Name SegmentaciónDeDatos_Numero_Economico: #N/A
Name SegmentaciónDeDatos_Tipo_de_Combustible: #N/A

Sheet Registro Diario
A1: CONTROL DE COMBUSTIBLE Y RENDIMIENTO DE FLOTA - REGISTRO DIARIO
A2: Captura cada carga de combustible. Las columnas en AZUL se llenan a mano; las columnas en NEGRO se calculan solas. Flota: 32 vehiculos.
A4: Item | B4: Fecha | C4: Numero Economico | D4: Kilometraje Inicial | E4: Kilometraje Actual (Final) | F4: Kilometraje Recorrido | G4: Tipo de Combustible | H4: Litros Cargados | I4: Precio por Litro | J4: Total Pesos | K4: Rendimiento (km/l)
A5: =ROW()-4 -> 1 | B5: 46237 | C5: U-549 | D5: 0 | E5: 213702 | F5: 213702 | G5: Diesel | H5: 30.054 | I5: 27 | J5: =H5*I5 -> 811.458 | K5: =IFERROR(F5/H5,0) -> 7110.6009
A6: =ROW()-4 -> 2 | B6: 46237 | C6: U-560 | D6: 0 | E6: 275208 | F6: =IFERROR(E6-D6,0) -> 275208 | G6: Diesel | H6: 44.007 | I6: 27 | J6: =H6*I6 -> 1188.189 | K6: =IFERROR(F6/H6,0) -> 6253.7324
A7: =ROW()-4 -> 3 | B7: 46237 | C7: U-576 | D7: 0 | E7: 111444 | F7: =IFERROR(E7-D7,0) -> 111444 | G7: Gasolina | H7: 86.407 | I7: 23.98 | J7: =H7*I7 -> 2072.0399 | K7: =IFERROR(F7/H7,0) -> 1289.7566
A8: =ROW()-4 -> 4 | B8: 46237 | C8: U-614 | D8: 0 | E8: 174669 | F8: =IFERROR(E8-D8,0) -> 174669 | G8: Gasolina | H8: 45.056 | I8: 23.98 | J8: =H8*I8 -> 1080.4429 | K8: =IFERROR(F8/H8,0) -> 3876.709
A9: =ROW()-4 -> 5 | B9: 46237 | C9: U-581 | D9: 0 | E9: 305289 | F9: =IFERROR(E9-D9,0) -> 305289 | G9: Gasolina | H9: 37.701 | I9: 23.98 | J9: =H9*I9 -> 904.06998 | K9: =IFERROR(F9/H9,0) -> 8097.6367
A10: =ROW()-4 -> 6 | B10: 46237 | C10: Maq. Soldar | D10: 0 | E10: 3538 | F10: =IFERROR(E10-D10,0) -> 3538 | G10: Diesel | H10: 26.451 | I10: 27 | J10: =H10*I10 -> 714.177 | K10: =IFERROR(F10/H10,0) -> 133.75676
A11: =ROW()-4 -> 7 | B11: 46238 | C11: U-592 | D11: 0 | E11: 248349 | F11: =IFERROR(E11-D11,0) -> 248349 | G11: Gasolina | H11: 42.846 | I11: 23.98 | J11: =H11*I11 -> 1027.4471 | K11: =IFERROR(F11/H11,0) -> 5796.317
A12: =ROW()-4 -> 8 | B12: 46238 | C12: U-614 | D12: =IF(C12="","",IFERROR(INDEX($E$5:$E$486,SUMPRODUCT(MAX(($C$5:$C$486=C12)*($A$5:$A$486<A12)*$A$5:$A$486))),"")) -> 174669 | E12: 174849 | F12: =IFERROR(E12-D12,0) -> 180 | G12: Gasolina | H12: 38.173 | I12: 23.98 | J12: =H12*I12 -> 915.38854 | K12: =IFERROR(F12/H12,0) -> 4.7153747
A13: =ROW()-4 -> 9 | B13: 46239 | C13: U-545 | D13: 0 | E13: 205752 | F13: =IFERROR(E13-D13,0) -> 205752 | G13: Diesel | H13: 47.727 | I13: 27 | J13: =H13*I13 -> 1288.629 | K13: =IFERROR(F13/H13,0) -> 4311.0189
A14: =ROW()-4 -> 10 | B14: 46239 | C14: U-598 | D14: 0 | E14: 268947 | F14: =IFERROR(E14-D14,0) -> 268947 | G14: Gasolina | H14: 53.456 | I14: 23.9799 | J14: =H14*I14 -> 1281.8695 | K14: =IFERROR(F14/H14,0) -> 5031.1845
A15: =ROW()-4 -> 11 | B15: 46239 | C15: U-614 | D15: =IF(C15="","",IFERROR(INDEX($E$5:$E$486,SUMPRODUCT(MAX(($C$5:$C$486=C15)*($A$5:$A$486<A15)*$A$5:$A$486))),"")) -> 174849 | E15: 175127 | F15: =IFERROR(E15-D15,0) -> 278 | G15: Gasolina | H15: 35.426 | I15: 23.9799 | J15: =H15*I15 -> 849.51194 | K15: =IFERROR(F15/H15,0) -> 7.8473438
A16: =ROW()-4 -> 12 | B16: 46239 | C16: U-581 | D16: =IF(C16="","",IFERROR(INDEX($E$5:$E$486,SUMPRODUCT(MAX(($C$5:$C$486=C16)*($A$5:$A$486<A16)*$A$5:$A$486))),"")) -> 305289 | E16: 305660 | F16: =IFERROR(E16-D16,0) -> 371 | G16: Gasolina | H16: 47.497 | I16: 28.98 | J16: =H16*I16 -> 1376.4631 | K16: =IFERROR(F16/H16,0) -> 7.8110196
A17: =ROW()-4 -> 13 | B17: 46240 | C17: U-338 | D17: 0 | E17: 170451 | F17: =IFERROR(E17-D17,0) -> 170451 | G17: Diesel | H17: 119.851 | I17: 27 | J17: =H17*I17 -> 3235.977 | K17: =IFERROR(F17/H17,0) -> 1422.1909
A18: =ROW()-4 -> 14 | B18: 46240 | C18: U-554 | D18: =IF(C18="","",IFERROR(INDEX($E$5:$E$486,SUMPRODUCT(MAX(($C$5:$C$486=C18)*($A$5:$A$486<A18)*$A$5:$A$486))),"")) -> 206519 | E18: 206519 | F18: =IFERROR(E18-D18,0) -> 0 | G18: Diesel | H18: 28.403 | I18: 27 | J18: =H18*I18 -> 766.881 | K18: =IFERROR(F18/H18,0) -> 0
A19: =ROW()-4 -> 15 | B19: 46240 | C19: U-560 | D19: =IF(C19="","",IFERROR(INDEX($E$5:$E$486,SUMPRODUCT(MAX(($C$5:$C$486=C19)*($A$5:$A$486<A19)*$A$5:$A$486))),"")) -> 275208 | E19: 275514 | F19: =IFERROR(E19-D19,0) -> 306 | G19: Diesel | H19: 48.449 | I19: 27 | J19: =H19*I19 -> 1308.123 | K19: =IFERROR(F19/H19,0) -> 6.3159198
A20: =ROW()-4 -> 16 | B20: 46240 | C20: U-614 | D20: =IF(C20="","",IFERROR(INDEX($E$5:$E$486,SUMPRODUCT(MAX(($C$5:$C$486=C20)*($A$5:$A$486<A20)*$A$5:$A$486))),"")) -> 175127 | E20: 175357 | F20: =IFERROR(E20-D20,0) -> 230 | G20: Gasolina | H20: 37.261 | I20: 23.98 | J20: =H20*I20 -> 893.51878 | K20: =IFERROR(F20/H20,0) -> 6.1726738
A21: =ROW()-4 -> 17 | B21: 46240 | C21: Celaje | D21: =IF(C21="","",IFERROR(INDEX($E$5:$E$486,SUMPRODUCT(MAX(($C$5:$C$486=C21)*($A$5:$A$486<A21)*$A$5:$A$486))),"")) -> 0 | F21: =IFERROR(E21-D21,0) -> 0 | G21: Gasolina | H21: 3 | I21: 23.98 | J21: =H21*I21 -> 71.94 | K21: =IFERROR(F21/H21,0) -> 0
A22: =ROW()-4 -> 18 | B22: 46241 | C22: U-293 | D22: =IF(C22="","",IFERROR(INDEX($E$5:$E$486,SUMPRODUCT(MAX(($C$5:$C$486=C22)*($A$5:$A$486<A22)*$A$5:$A$486))),"")) -> 530546 | E22: 530546 | F22: =IFERROR(E22-D22,0) -> 0 | G22: Gasolina | H22: 25.143 | I22: 23.98 | J22: =H22*I22 -> 602.92914 | K22: =IFERROR(F22/H22,0) -> 0
A23: =ROW()-4 -> 19 | B23: 46241 | C23: U-549 | D23: =IF(C23="","",IFERROR(INDEX($E$5:$E$486,SUMPRODUCT(MAX(($C$5:$C$486=C23)*($A$5:$A$486<A23)*$A$5:$A$486))),"")) -> 213702 | E23: 214087 | F23: =IFERROR(E23-D23,0) -> 385 | G23: Diesel | H23: 56.947 | I23: 27 | J23: =H23*I23 -> 1537.569 | K23: =IFERROR(F23/H23,0) -> 6.7606722
A24: =ROW()-4 -> 20 | B24: 46241 | C24: U-551 | D24: =IF(C24="","",IFERROR(INDEX($E$5:$E$486,SUMPRODUCT(MAX(($C$5:$C$486=C24)*($A$5:$A$486<A24)*$A$5:$A$486))),"")) -> 183057 | E24: 183057 | F24: =IFERROR(E24-D24,0) -> 0 | G24: Diesel | H24: 58.141 | I24: 27 | J24: =H24*I24 -> 1569.807 | K24: =IFERROR(F24/H24,0) -> 0
A25: =ROW()-4 -> 21 | B25: 46241 | C25: U-562 | D25: =IF(C25="","",IFERROR(INDEX($E$5:$E$486,SUMPRODUCT(MAX(($C$5:$C$486=C25)*($A$5:$A$486<A25)*$A$5:$A$486))),"")) -> 205992 | E25: 205992 | F25: =IFERROR(E25-D25,0) -> 0 | G25: Diesel | H25: 55.235 | I25: 27 | J25: =H25*I25 -> 1491.345 | K25: =IFERROR(F25/H25,0) -> 0
A26: =ROW()-4 -> 22 | B26: 46241 | C26: U-588 | D26: =IF(C26="","",IFERROR(INDEX($E$5:$E$486,SUMPRODUCT(MAX(($C$5:$C$486=C26)*($A$5:$A$486<A26)*$A$5:$A$486))),"")) -> 309157 | E26: 309157 | F26: =IFERROR(E26-D26,0) -> 0 | G26: Gasolina | H26: 64.49 | I26: 23.98 | J26: =H26*I26 -> 1546.4702 | K26: =IFERROR(F26/H26,0) -> 0
A27: =ROW()-4 -> 23 | B27: 46241 | C27: U-592 | D27: =IF(C27="","",IFERROR(INDEX($E$5:$E$486,SUMPRODUCT(MAX(($C$5:$C$486=C27)*($A$5:$A$486<A27)*$A$5:$A$486))),"")) -> 248349 | E27: 248743 | F27: =IFERROR(E27-D27,0) -> 394 | G27: Gasolina | H27: 60.217 | I27: 28.98 | J27: =H27*I27 -> 1745.0887 | K27: =IFERROR(F27/H27,0) -> 6.5430028
A28: =ROW()-4 -> 24 | B28: 46241 | C28: U-614 | D28: =IF(C28="","",IFERROR(INDEX($E$5:$E$486,SUMPRODUCT(MAX(($C$5:$C$486=C28)*($A$5:$A$486<A28)*$A$5:$A$486))),"")) -> 175357 | E28: 175565 | F28: =IFERROR(E28-D28,0) -> 208 | G28: Gasolina | H28: 31.936 | I28: 28.98 | J28: =H28*I28 -> 925.50528 | K28: =IFERROR(F28/H28,0) -> 6.5130261
A29: =ROW()-4 -> 25 | B29: 46241 | C29: U-674 | D29: =IF(C29="","",IFERROR(INDEX($E$5:$E$486,SUMPRODUCT(MAX(($C$5:$C$486=C29)*($A$5:$A$486<A29)*$A$5:$A$486))),"")) -> 4509 | E29: 4509 | F29: =IFERROR(E29-D29,0) -> 0 | G29: Gasolina | H29: 39.205 | I29: 23.98 | J29: =H29*I29 -> 940.1359 | K29: =IFERROR(F29/H29,0) -> 0
A30: =ROW()-4 -> 26 | B30: 46241 | C30: U-581 | D30: =IF(C30="","",IFERROR(INDEX($E$5:$E$486,SUMPRODUCT(MAX(($C$5:$C$486=C30)*($A$5:$A$486<A30)*$A$5:$A$486))),"")) -> 305660 | E30: 306015 | F30: =IFERROR(E30-D30,0) -> 355 | G30: Gasolina | H30: 42.497 | I30: 23.98 | J30: =H30*I30 -> 1019.0781 | K30: =IFERROR(F30/H30,0) -> 8.3535308
A31: =ROW()-4 -> 27 | B31: 46244 | C31: U-551 | D31: =IF(C31="","",IFERROR(INDEX($E$5:$E$486,SUMPRODUCT(MAX(($C$5:$C$486=C31)*($A$5:$A$486<A31)*$A$5:$A$486))),"")) -> 183057 | E31: 183316 | F31: =IFERROR(E31-D31,0) -> 259 | G31: Diesel | H31: 41.955 | I31: 27 | J31: =H31*I31 -> 1132.785 | K31: =IFERROR(F31/H31,0) -> 6.1732809
A32: =ROW()-4 -> 28 | B32: 46244 | C32: U-554 | D32: =IF(C32="","",IFERROR(INDEX($E$5:$E$486,SUMPRODUCT(MAX(($C$5:$C$486=C32)*($A$5:$A$486<A32)*$A$5:$A$486))),"")) -> 206519 | E32: 206699 | F32: =IFERROR(E32-D32,0) -> 180 | G32: Diesel | H32: 33.938 | I32: 27 | J32: =H32*I32 -> 916.326 | K32: =IFERROR(F32/H32,0) -> 5.3037893
A33: =ROW()-4 -> 29 | B33: 46244 | C33: U-560 | D33: =IF(C33="","",IFERROR(INDEX($E$5:$E$486,SUMPRODUCT(MAX(($C$5:$C$486=C33)*($A$5:$A$486<A33)*$A$5:$A$486))),"")) -> 275514 | E33: 275697 | F33: =IFERROR(E33-D33,0) -> 183 | G33: Diesel | H33: 31.165 | I33: 27 | J33: =H33*I33 -> 841.455 | K33: =IFERROR(F33/H33,0) -> 5.8719718
... A43: =ROW()-4 -> 39 | B43: 46245 | C43: U-675 | D43: =IF(C43="","",IFERROR(INDEX($E$5:$E$486,SUMPRODUCT(MAX(($C$5:$C$486=C43)*($A$5:$A$486<A43)*$A$5:$A$486))),"")) -> 1142 | E43: 1142 | F43: =IFERROR(E43-D43,0) -> 0 | G43: Diesel | H43: 41.33 | I43: 27 | J43: =H43*I43 -> 1115.91 | K43: =IFERROR(F43/H43,0) -> 0
A44: =ROW()-4 -> 40 | B44: 46245 | C44: Celaje | D44: =IF(C44="","",IFERROR(INDEX($E$5:$E$486,SUMPRODUCT(MAX(($C$5:$C$486=C44)*($A$5:$A$486<A44)*$A$5:$A$486))),"")) -> 0 | F44: =IFERROR(E44-D44,0) -> 0 | G44: Gasolina | H44: 4 | I44: 23.98 | J44: =H44*I44 -> 95.92 | K44: =IFERROR(F44/H44,0) -> 0
A45: =ROW()-4 -> 41 | B45: 46246 | C45: U-614 | D45: =IF(C45="","",IFERROR(INDEX($E$5:$E$486,SUMPRODUCT(MAX(($C$5:$C$486=C45)*($A$5:$A$486<A45)*$A$5:$A$486))),"")) -> 176000 | E45: 176217 | F45: =IFERROR(E45-D45,0) -> 217 | G45: Gasolina | H45: 30.815 | I45: 23.98 | J45: =H45*I45 -> 738.9437 | K45: =IFERROR(F45/H45,0) -> 7.042025
A46: =ROW()-4 -> 42 | B46: 46247 | C46: U-338 | D46: =IF(C46="","",IFERROR(INDEX($E$5:$E$486,SUMPRODUCT(MAX(($C$5:$C$486=C46)*($A$5:$A$486<A46)*$A$5:$A$486))),"")) -> 170451 | E46: 170787 | F46: =IFERROR(E46-D46,0) -> 336 | G46: Diesel | H46: 122.003 | I46: 27 | J46: =H46*I46 -> 3294.081 | K46: =IFERROR(F46/H46,0) -> 2.7540306
A47: =ROW()-4 -> 43 | B47: 46247 | C47: U-551 | D47: =IF(C47="","",IFERROR(INDEX($E$5:$E$486,SUMPRODUCT(MAX(($C$5:$C$486=C47)*($A$5:$A$486<A47)*$A$5:$A$486))),"")) -> 183316 | E47: 183600 | F47: =IFERROR(E47-D47,0) -> 284 | G47: Diesel | H47: 50.949 | I47: 27 | J47: =H47*I47 -> 1375.623 | K47: =IFERROR(F47/H47,0) -> 5.5742017
A48: =ROW()-4 -> 44 | B48: 46247 | C48: U-614 | D48: =IF(C48="","",IFERROR(INDEX($E$5:$E$486,SUMPRODUCT(MAX(($C$5:$C$486=C48)*($A$5:$A$486<A48)*$A$5:$A$486))),"")) -> 176217 | E48: 176416 | F48: =IFERROR(E48-D48,0) -> 199 | G48: Gasolina | H48: 29.061 | I48: 23.98 | J48: =H48*I48 -> 696.88278 | K48: =IFERROR(F48/H48,0) -> 6.8476653
A49: =ROW()-4 -> 45 | B49: 46247 | C49: U-598 | D49: =IF(C49="","",IFERROR(INDEX($E$5:$E$486,SUMPRODUCT(MAX(($C$5:$C$486=C49)*($A$5:$A$486<A49)*$A$5:$A$486))),"")) -> 269257 | E49: 269602 | F49: =IFERROR(E49-D49,0) -> 345 | G49: Gasolina | H49: 39.67 | I49: 23.98 | J49: =H49*I49 -> 951.2866 | K49: =IFERROR(F49/H49,0) -> 8.6967482
A50: =ROW()-4 -> 46 | B50: 46247 | C50: otros | D50: =IF(C50="","",IFERROR(INDEX($E$5:$E$486,SUMPRODUCT(MAX(($C$5:$C$486=C50)*($A$5:$A$486<A50)*$A$5:$A$486))),"")) -> 0 | F50: =IFERROR(E50-D50,0) -> 0 | G50: Gasolina | H50: 3 | I50: 23.98 | J50: =H50*I50 -> 71.94 | K50: =IFERROR(F50/H50,0) -> 0
...

Sheet Resumen Semanal
A3: Suma de Total Pesos | B3: Etiquetas de columna
A4: Etiquetas de fila | B4: Diesel | C4: Gasolina | D4: Total general
A5: 29/09/2026 - 05/10/2026 | B5: 11659.464 | C5: 22018.916 | D5: 33678.38
A6: Total general | B6: 11659.464 | C6: 22018.916 | D6: 33678.38

Sheet Resumen Mensual
A1: RESUMEN MENSUAL POR VEHICULO
A2: Cambia el Mes y el Ano en las celdas amarillas; el resumen se recalcula solo.
A4: Mes (1-12): | B4: 8 | C4: Ano: | D4: 2026 | E4: Inicio periodo: | F4: =DATE(D4,B4,1) -> 46235 | G4: Fin periodo: | H4: =EOMONTH(F4,0) -> 46265
A6: Numero Economico | B6: Total KM Recorridos | C6: Total Litros Cargados | D6: Gasto Total ($) | E6: Rendimiento Promedio Real (km/l)
A7: =Listas!A2 -> U-260 | B7: =SUMIFS('Registro Diario'!$F$5:$F$486,'Registro Diario'!$C$5:$C$486,A7,'Registro Diario'!$B$5:$B$486,">="&$F$4,'Registro Diario'!$B$5:$B$486,"<="&$H$4) -> 0 | C7: =SUMIFS('Registro Diario'!$H$5:$H$486,'Registro Diario'!$C$5:$C$486,A7,'Registro Diario'!$B$5:$B$486,">="&$F$4,'Registro Diario'!$B$5:$B$486,"<="&$H$4) -> 0 | D7: =SUMIFS('Registro Diario'!$J$5:$J$486,'Registro Diario'!$C$5:$C$486,A7,'Registro Diario'!$B$5:$B$486,">="&$F$4,'Registro Diario'!$B$5:$B$486,"<="&$H$4) -> 0 | E7: =IFERROR(B7/C7,0) -> 0
A8: =Listas!A4 -> U-274 | B8: =SUMIFS('Registro Diario'!$F$5:$F$486,'Registro Diario'!$C$5:$C$486,A8,'Registro Diario'!$B$5:$B$486,">="&$F$4,'Registro Diario'!$B$5:$B$486,"<="&$H$4) -> 219 | C8: =SUMIFS('Registro Diario'!$H$5:$H$486,'Registro Diario'!$C$5:$C$486,A8,'Registro Diario'!$B$5:$B$486,">="&$F$4,'Registro Diario'!$B$5:$B$486,"<="&$H$4) -> 192.892 | D8: =SUMIFS('Registro Diario'!$J$5:$J$486,'Registro Diario'!$C$5:$C$486,A8,'Registro Diario'!$B$5:$B$486,">="&$F$4,'Registro Diario'!$B$5:$B$486,"<="&$H$4) -> 5208.084 | E8: =IFERROR(B8/C8,0) -> 1.1353504
A9: =Listas!A5 -> U-293 | B9: =SUMIFS('Registro Diario'!$F$5:$F$486,'Registro Diario'!$C$5:$C$486,A9,'Registro Diario'!$B$5:$B$486,">="&$F$4,'Registro Diario'!$B$5:$B$486,"<="&$H$4) -> 288 | C9: =SUMIFS('Registro Diario'!$H$5:$H$486,'Registro Diario'!$C$5:$C$486,A9,'Registro Diario'!$B$5:$B$486,">="&$F$4,'Registro Diario'!$B$5:$B$486,"<="&$H$4) -> 68.732 | D9: =SUMIFS('Registro Diario'!$J$5:$J$486,'Registro Diario'!$C$5:$C$486,A9,'Registro Diario'!$B$5:$B$486,">="&$F$4,'Registro Diario'!$B$5:$B$486,"<="&$H$4) -> 1648.1934 | E9: =IFERROR(B9/C9,0) -> 4.190188
A10: =Listas!A6 -> U-337 | B10: =SUMIFS('Registro Diario'!$F$5:$F$486,'Registro Diario'!$C$5:$C$486,A10,'Registro Diario'!$B$5:$B$486,">="&$F$4,'Registro Diario'!$B$5:$B$486,"<="&$H$4) -> 0 | C10: =SUMIFS('Registro Diario'!$H$5:$H$486,'Registro Diario'!$C$5:$C$486,A10,'Registro Diario'!$B$5:$B$486,">="&$F$4,'Registro Diario'!$B$5:$B$486,"<="&$H$4) -> 145.854 | D10: =SUMIFS('Registro Diario'!$J$5:$J$486,'Registro Diario'!$C$5:$C$486,A10,'Registro Diario'!$B$5:$B$486,">="&$F$4,'Registro Diario'!$B$5:$B$486,"<="&$H$4) -> 3938.058 | E10: =IFERROR(B10/C10,0) -> 0
A11: =Listas!A7 -> U-338 | B11: =SUMIFS('Registro Diario'!$F$5:$F$486,'Registro Diario'!$C$5:$C$486,A11,'Registro Diario'!$B$5:$B$486,">="&$F$4,'Registro Diario'!$B$5:$B$486,"<="&$H$4) -> 170787 | C11: =SUMIFS('Registro Diario'!$H$5:$H$486,'Registro Diario'!$C$5:$C$486,A11,'Registro Diario'!$B$5:$B$486,">="&$F$4,'Registro Diario'!$B$5:$B$486,"<="&$H$4) -> 241.854 | D11: =SUMIFS('Registro Diario'!$J$5:$J$486,'Registro Diario'!$C$5:$C$486,A11,'Registro Diario'!$B$5:$B$486,">="&$F$4,'Registro Diario'!$B$5:$B$486,"<="&$H$4) -> 6530.058 | E11: =IFERROR(B11/C11,0) -> 706.15743
A12: =Listas!A8 -> U-434 | B12: =SUMIFS('Registro Diario'!$F$5:$F$486,'Registro Diario'!$C$5:$C$486,A12,'Registro Diario'!$B$5:$B$486,">="&$F$4,'Registro Diario'!$B$5:$B$486,"<="&$H$4) -> 0 | C12: =SUMIFS('Registro Diario'!$H$5:$H$486,'Registro Diario'!$C$5:$C$486,A12,'Registro Diario'!$B$5:$B$486,">="&$F$4,'Registro Diario'!$B$5:$B$486,"<="&$H$4) -> 0 | D12: =SUMIFS('Registro Diario'!$J$5:$J$486,'Registro Diario'!$C$5:$C$486,A12,'Registro Diario'!$B$5:$B$486,">="&$F$4,'Registro Diario'!$B$5:$B$486,"<="&$H$4) -> 0 | E12: =IFERROR(B12/C12,0) -> 0
A13: =Listas!A9 -> U-460 | B13: =SUMIFS('Registro Diario'!$F$5:$F$486,'Registro Diario'!$C$5:$C$486,A13,'Registro Diario'!$B$5:$B$486,">="&$F$4,'Registro Diario'!$B$5:$B$486,"<="&$H$4) -> 0 | C13: =SUMIFS('Registro Diario'!$H$5:$H$486,'Registro Diario'!$C$5:$C$486,A13,'Registro Diario'!$B$5:$B$486,">="&$F$4,'Registro Diario'!$B$5:$B$486,"<="&$H$4) -> 0 | D13: =SUMIFS('Registro Diario'!$J$5:$J$486,'Registro Diario'!$C$5:$C$486,A13,'Registro Diario'!$B$5:$B$486,">="&$F$4,'Registro Diario'!$B$5:$B$486,"<="&$H$4) -> 0 | E13: =IFERROR(B13/C13,0) -> 0
A14: =Listas!A10 -> U-468 | B14: =SUMIFS('Registro Diario'!$F$5:$F$486,'Registro Diario'!$C$5:$C$486,A14,'Registro Diario'!$B$5:$B$486,">="&$F$4,'Registro Diario'!$B$5:$B$486,"<="&$H$4) -> 0 | C14: =SUMIFS('Registro Diario'!$H$5:$H$486,'Registro Diario'!$C$5:$C$486,A14,'Registro Diario'!$B$5:$B$486,">="&$F$4,'Registro Diario'!$B$5:$B$486,"<="&$H$4) -> 0 | D14: =SUMIFS('Registro Diario'!$J$5:$J$486,'Registro Diario'!$C$5:$C$486,A14,'Registro Diario'!$B$5:$B$486,">="&$F$4,'Registro Diario'!$B$5:$B$486,"<="&$H$4) -> 0 | E14: =IFERROR(B14/C14,0) -> 0
A15: =Listas!A11 -> U-477 | B15: =SUMIFS('Registro Diario'!$F$5:$F$486,'Registro Diario'!$C$5:$C$486,A15,'Registro Diario'!$B$5:$B$486,">="&$F$4,'Registro Diario'!$B$5:$B$486,"<="&$H$4) -> 0 | C15: =SUMIFS('Registro Diario'!$H$5:$H$486,'Registro Diario'!$C$5:$C$486,A15,'Registro Diario'!$B$5:$B$486,">="&$F$4,'Registro Diario'!$B$5:$B$486,"<="&$H$4) -> 0 | D15: =SUMIFS('Registro Diario'!$J$5:$J$486,'Registro Diario'!$C$5:$C$486,A15,'Registro Diario'!$B$5:$B$486,">="&$F$4,'Registro Diario'!$B$5:$B$486,"<="&$H$4) -> 0 | E15: =IFERROR(B15/C15,0) -> 0
A16: =Listas!A12 -> U-545 | B16: =SUMIFS('Registro Diario'!$F$5:$F$486,'Registro Diario'!$C$5:$C$486,A16,'Registro Diario'!$B$5:$B$486,">="&$F$4,'Registro Diario'!$B$5:$B$486,"<="&$H$4) -> 206510 | C16: =SUMIFS('Registro Diario'!$H$5:$H$486,'Registro Diario'!$C$5:$C$486,A16,'Registro Diario'!$B$5:$B$486,">="&$F$4,'Registro Diario'!$B$5:$B$486,"<="&$H$4) -> 157.802 | D16: =SUMIFS('Registro Diario'!$J$5:$J$486,'Registro Diario'!$C$5:$C$486,A16,'Registro Diario'!$B$5:$B$486,">="&$F$4,'Registro Diario'!$B$5:$B$486,"<="&$H$4) -> 4260.654 | E16: =IFERROR(B16/C16,0) -> 1308.6653
A17: =Listas!A13 -> U-549 | B17: =SUMIFS('Registro Diario'!$F$5:$F$486,'Registro Diario'!$C$5:$C$486,A17,'Registro Diario'!$B$5:$B$486,">="&$F$4,'Registro Diario'!$B$5:$B$486,"<="&$H$4) -> 214087 | C17: =SUMIFS('Registro Diario'!$H$5:$H$486,'Registro Diario'!$C$5:$C$486,A17,'Registro Diario'!$B$5:$B$486,">="&$F$4,'Registro Diario'!$B$5:$B$486,"<="&$H$4) -> 87.001 | D17: =SUMIFS('Registro Diario'!$J$5:$J$486,'Registro Diario'!$C$5:$C$486,A17,'Registro Diario'!$B$5:$B$486,">="&$F$4,'Registro Diario'!$B$5:$B$486,"<="&$H$4) -> 2349.027 | E17: =IFERROR(B17/C17,0) -> 2460.7418
A18: =Listas!A14 -> U-551 | B18: =SUMIFS('Registro Diario'!$F$5:$F$486,'Registro Diario'!$C$5:$C$486,A18,'Registro Diario'!$B$5:$B$486,">="&$F$4,'Registro Diario'!$B$5:$B$486,"<="&$H$4) -> 975 | C18: =SUMIFS('Registro Diario'!$H$5:$H$486,'Registro Diario'!$C$5:$C$486,A18,'Registro Diario'!$B$5:$B$486,">="&$F$4,'Registro Diario'!$B$5:$B$486,"<="&$H$4) -> 245.484 | D18: =SUMIFS('Registro Diario'!$J$5:$J$486,'Registro Diario'!$C$5:$C$486,A18,'Registro Diario'!$B$5:$B$486,">="&$F$4,'Registro Diario'!$B$5:$B$486,"<="&$H$4) -> 6628.068 | E18: =IFERROR(B18/C18,0) -> 3.9717456
A19: =Listas!A15 -> U-554 | B19: =SUMIFS('Registro Diario'!$F$5:$F$486,'Registro Diario'!$C$5:$C$486,A19,'Registro Diario'!$B$5:$B$486,">="&$F$4,'Registro Diario'!$B$5:$B$486,"<="&$H$4) -> 845 | C19: =SUMIFS('Registro Diario'!$H$5:$H$486,'Registro Diario'!$C$5:$C$486,A19,'Registro Diario'!$B$5:$B$486,">="&$F$4,'Registro Diario'!$B$5:$B$486,"<="&$H$4) -> 207.438 | D19: =SUMIFS('Registro Diario'!$J$5:$J$486,'Registro Diario'!$C$5:$C$486,A19,'Registro Diario'!$B$5:$B$486,">="&$F$4,'Registro Diario'!$B$5:$B$486,"<="&$H$4) -> 5600.826 | E19: =IFERROR(B19/C19,0) -> 4.0735063
... A43: =Listas!A39 -> Bateria Soledad Sur 2 | B43: =SUMIFS('Registro Diario'!$F$5:$F$486,'Registro Diario'!$C$5:$C$486,A43,'Registro Diario'!$B$5:$B$486,">="&$F$4,'Registro Diario'!$B$5:$B$486,"<="&$H$4) -> 0 | C43: =SUMIFS('Registro Diario'!$H$5:$H$486,'Registro Diario'!$C$5:$C$486,A43,'Registro Diario'!$B$5:$B$486,">="&$F$4,'Registro Diario'!$B$5:$B$486,"<="&$H$4) -> 50 | D43: =SUMIFS('Registro Diario'!$J$5:$J$486,'Registro Diario'!$C$5:$C$486,A43,'Registro Diario'!$B$5:$B$486,">="&$F$4,'Registro Diario'!$B$5:$B$486,"<="&$H$4) -> 5000 | E43: =IFERROR(B43/C43,0) -> 0
A46: TOTAL FLOTA | B46: =SUM(B7:B45) -> 2001285 | C46: =SUM(C7:C45) -> 5296.097 | D46: =SUM(D7:D45) -> 142655.87 | E46: =IFERROR(B46/C46,0) -> 377.87922

Sheet Graficos
A1: COMPARATIVO DE RENDIMIENTO POR VEHICULO
A2: Estos graficos se alimentan automaticamente de la hoja Resumen Mensual.

Sheet Listas
A1: Numero_Economico | B1: Tipo_Combustible | C1: Tipo de Combustible Asignado
A2: U-260 | B2: Gasolina | C2: Gasolina
A3: U-272 | B3: Gasolina | C3: Diesel
A4: U-274 | B4: Diesel | C4: Diesel
A5: U-293 | B5: Gasolina | C5: Gasolina
A6: U-337 | B6: Diesel | C6: Diesel
A7: U-338 | B7: Diesel | C7: Diesel
A8: U-434 | B8: Gasolina | C8: Gasolina
A9: U-460 | B9: Gasolina | C9: Gasolina
A10: U-468 | B10: Gasolina | C10: Gasolina
A11: U-477 | B11: Gasolina | C11: Gasolina
A12: U-545 | B12: Diesel | C12: Diesel
... A39: Bateria Soledad Sur 2 | B39: Gasolina | C39: Gasolina
